Workbook

Sheet ROW_Music_Festival_Data
A1: Festival_Name | B1: City | C1: Date | D1: Tour_Name | E1: Headlining_Artist | F1: Supporting_Artists | G1: Ticket_Price(Rs) | H1: Total_Attendance | I1: Merchandise_Sales (Rs) | J1: Sponsorship_Revenue (Rs) | K1: Total_Revenue (Rs)
A2: NH7 Pune | B2: Kolkata | C2: 45303 | E2: Badshah | F2: DJ Snake, Honey Singh | G2: 1253 | H2: 6166 | I2: 1942290 | J2: 3680408 | K2: 13348696
A3: Ziro Festival Arunachal | B3: Delhi | C3: 45403 | E3: Honey Singh | F3: Bryan Adams, Martin Garrix, Mika Singh | G3: 1689 | H3: 40643 | I3: 16622987 | J3: 2589481 | K3: 87858495
A4: NH7 Pune | B4: Bengaluru | C4: 45553 | D4: Classics Tour | E4: Bryan Adams | F4: Badshah, Arijit Singh, Martin Garrix, Diljit Dosanjh | G4: 6813.8 | H4: 17889.9 | I4: 7667100 | J4: 640053 | K4: 132693072
A5: VH1 Supersonic Delhi | B5: Goa | C5: 45353 | E5: Honey Singh | F5: Martin Garrix, Badshah, Ed Sheeran, Diljit Dosanjh | G5: 2144 | H5: 14688 | I5: 2350080 | J5: 2712686 | K5: 36553838
A6: Hornbill Festival Nagaland | B6: Nagpur | C6: 45454 | D6: Soulful Nights Tour | E6: Arijit Singh | F6: Martin Garrix, Badshah | G6: 1886 | H6: 35244 | I6: 6132456 | J6: 1181193 | K6: 73783833
A7: Ziro Festival Arunachal | B7: Jaipur | C7: 45437 | E7: Mika Singh | F7: Diljit Dosanjh, Mika Singh | G7: 3984 | I7: 2252122 | J7: 2302603 | K7: 58605653
A8: Ziro Festival Arunachal | B8: Goa | C8: 45371 | D8: Classics Tour | E8: Bryan Adams | F8: Ed Sheeran, Mika Singh, Shreya Ghoshal, Bryan Adams | H8: 18778.2 | I8: 4828680 | J8: 4948076 | K8: 111635078
A9: NH7 Pune | B9: Nagpur | C9: 45462 | E9: Badshah | F9: Honey Singh, Badshah, Bryan Adams, Martin Garrix | G9: 840 | H9: 33535 | I9: 12206740 | J9: 1201595 | K9: 41577735
A10: Bollywood Music Project | B10: Delhi | C10: 45440 | E10: Shreya Ghoshal | F10: Ed Sheeran, Shreya Ghoshal, Bryan Adams, Badshah | G10: 4191 | I10: 4279770 | J10: 3427104 | K10: 81824709
A11: Lollapalooza Mumbai | B11: Kolkata | C11: 45319 | E11: Honey Singh | F11: Honey Singh, Diljit Dosanjh | G11: 1823 | H11: 15513 | I11: 7539318 | J11: 3948781 | K11: 39768298
A12: Hornbill Festival Nagaland | B12: Jaipur | C12: 45462 | E12: DJ Snake | F12: Honey Singh, Diljit Dosanjh, Arijit Singh | G12: 3953.6 | H12: 21693 | I12: 9306297 | J12: 4798020 | K12: 75365349
A13: Sunburn Goa | B13: Goa | C13: 45649 | E13: Shreya Ghoshal | F13: Honey Singh, Badshah, Bryan Adams | G13: 2842 | H13: 24021 | I13: 5020389 | J13: 2851905 | K13: 76139976
A14: Supersonic Bengaluru | B14: Pune | C14: 45428 | D14: Born To Shine Tour | E14: Diljit Dosanjh | F14: Mika Singh, Ed Sheeran, Arijit Singh | G14: 528 | H14: 33241 | I14: 2659280 | J14: 3167786 | K14: 19328026
A15: Magnetic Fields Rajasthan | B15: Mumbai | C15: 45644 | E15: Martin Garrix | F15: Shreya Ghoshal, Ed Sheeran, Arijit Singh | G15: 1543 | H15: 19867 | I15: 2821114 | J15: 2897760 | K15: 36373655
A16: Hornbill Festival Nagaland | B16: Amritsar | C16: 45344 | E16: Shreya Ghoshal | F16: Bryan Adams, Badshah, Honey Singh | G16: 2188 | H16: 20603 | I16: 9559792 | J16: 4600450 | K16: 59239606
A17: VH1 Supersonic Delhi | B17: Kolkata | C17: 45581 | D17: Classics Tour | E17: Bryan Adams | F17: Ed Sheeran, Shreya Ghoshal | G17: 2217.6 | H17: 9504.6 | I17: 5892852 | J17: 795307 | K17: 28195711
A18: Lollapalooza Mumbai | B18: Delhi | C18: 45455 | D18: Classics Tour | E18: Bryan Adams | F18: Martin Garrix, Mika Singh, Bryan Adams | G18: 5397 | H18: 9158.1 | I18: 1687707 | J18: 2188470 | K18: 54311142
A19: Ziro Festival Arunachal | B19: Pune | C19: 45384 | D19: Mathematics Tour | E19: Ed Sheeran | F19: Honey Singh, Ed Sheeran | G19: 1601.6 | H19: 11790 | I19: 3030030 | J19: 3635278 | K19: 20153068
A20: Ziro Festival Arunachal | B20: Delhi | C20: 45531 | E20: Shreya Ghoshal | F20: Honey Singh, Mika Singh, Martin Garrix, Ed Sheeran | G20: 4564 | H20: 31755 | I20: 6890835 | J20: 4732974 | K20: 156553629
A21: Sunburn Goa | B21: Nagpur | C21: 45634 | D21: Classics Tour | E21: Bryan Adams | F21: Ed Sheeran, Mika Singh, Shreya Ghoshal, Honey Singh | G21: 3350.2 | H21: 2975.7 | I21: 1041495 | J21: 3001940 | K21: 14216078
A22: Sunburn Goa | B22: Delhi | C22: 45460 | E22: Badshah | F22: Shreya Ghoshal, Diljit Dosanjh, Arijit Singh | G22: 4045 | H22: 27719 | I22: 7539568 | J22: 4670910 | K22: 124333833
A23: Sunburn Goa | B23: Bengaluru | C23: 45425 | D23: Soulful Nights Tour | E23: Arijit Singh | F23: Honey Singh, Diljit Dosanjh, Badshah | G23: 1008 | H23: 21142 | I23: 2558182 | J23: 1632574 | K23: 25501892
A24: NH7 Pune | B24: Chandigarh | C24: 45474 | E24: Martin Garrix | F24: Honey Singh, Bryan Adams, DJ Snake | G24: 2334 | H24: 16842 | I24: 6905220 | J24: 1067015 | K24: 47281463
A25: Goa Tribal Festival | B25: Delhi | C25: 45299 | D25: Born To Shine Tour | E25: Diljit Dosanjh | F25: Ed Sheeran, Diljit Dosanjh, Shreya Ghoshal, Badshah | H25: 14456 | I25: 4603680 | J25: 2403962 | K25: 41090442
A26: Magnetic Fields Rajasthan | B26: Amritsar | C26: 45416 | E26: Badshah | F26: Mika Singh, Diljit Dosanjh, Martin Garrix | G26: 3977 | H26: 25243 | I26: 9238938 | J26: 4689343 | K26: 114319692
A27: Sunburn Goa | B27: Jaipur | C27: 45407 | E27: Honey Singh | F27: Bryan Adams, Diljit Dosanjh, Honey Singh, Mika Singh | G27: 3449 | H27: 13539 | I27: 5672841 | J27: 3471436 | K27: 55840288
A28: Hornbill Festival Nagaland | B28: Pune | C28: 45316 | E28: Badshah | F28: Martin Garrix, Bryan Adams, DJ Snake | G28: 3668 | H28: 36462 | I28: 5250528 | J28: 2377592 | K28: 141370736
A29: NH7 Pune | B29: Goa | C29: 45539 | E29: Badshah | F29: Arijit Singh, Diljit Dosanjh | G29: 3279 | H29: 32540 | I29: 13341400 | J29: 2840750 | K29: 122880810
A30: NH7 Pune | B30: Amritsar | C30: 45639 | E30: Honey Singh | F30: Diljit Dosanjh, Honey Singh, DJ Snake, Shreya Ghoshal | G30: 2948 | H30: 9316 | I30: 1266976 | J30: 2704822 | K30: 31435366
A31: NH7 Pune | B31: Delhi | C31: 45647 | E31: DJ Snake | F31: Bryan Adams, Mika Singh, Arijit Singh | G31: 2749.6 | H31: 17172 | I31: 7830432 | J31: 3956927 | K31: 45513167
A32: Ziro Festival Arunachal | B32: Bengaluru | C32: 45410 | E32: Honey Singh | F32: Arijit Singh, Honey Singh | H32: 16737 | I32: 6276375 | J32: 2726932 | K32: 85424449
A33: NH7 Pune | B33: Chandigarh | C33: 45392 | E33: Shreya Ghoshal | F33: Martin Garrix, Diljit Dosanjh, Badshah, Mika Singh | G33: 632 | H33: 35304 | I33: 10379376 | J33: 1590737 | K33: 34282241
A34: Goa Tribal Festival | B34: Kolkata | C34: 45360 | E34: Honey Singh | F34: DJ Snake, Arijit Singh, Badshah, Mika Singh | G34: 1932 | H34: 16841 | I34: 7713178 | J34: 4738764 | K34: 44988754
A35: Ziro Festival Arunachal | B35: Goa | C35: 45358 | D35: Classics Tour | E35: Bryan Adams | F35: Mika Singh, Diljit Dosanjh, Shreya Ghoshal | G35: 1598.8 | H35: 18210.5 | I35: 7336230 | J35: 2229062 | K35: 39274422
A36: NH7 Pune | B36: Delhi | C36: 45326 | D36: Born To Shine Tour | E36: Diljit Dosanjh | F36: Mika Singh, Ed Sheeran, Honey Singh, Diljit Dosanjh | G36: 1933 | H36: 58687.2 | I36: 16296984 | J36: 1120895 | K36: 104681231
A37: Lollapalooza Mumbai | B37: Bengaluru | C37: 45395 | D37: Born To Shine Tour | E37: Diljit Dosanjh | F37: Diljit Dosanjh, DJ Snake, Honey Singh, Shreya Ghoshal | H37: 7559.5 | I37: 1913135 | J37: 4680189 | K37: 21654174
A38: VH1 Supersonic Delhi | B38: Bengaluru | C38: 45509 | E38: Martin Garrix | F38: DJ Snake, Honey Singh, Diljit Dosanjh | G38: 4452 | H38: 31745 | I38: 4412555 | J38: 4091720 | K38: 149833015
A39: Bollywood Music Project | B39: Mumbai | C39: 45555 | E39: Mika Singh | F39: Arijit Singh, DJ Snake, Martin Garrix | G39: 2716 | H39: 12688 | I39: 2486848 | J39: 1413822 | K39: 38361278
A40: Sunburn Goa | B40: Chandigarh | C40: 45507 | E40: Mika Singh | F40: DJ Snake, Badshah | G40: 2237 | H40: 20276 | I40: 9671652 | J40: 4912334 | K40: 59941398
...

Sheet ROW_Artist_Popularity_Data
A1: Artist_Name | B1: Genre | C1: Average_Ticket_Price | D1: Average_Attendance_Per_City | E1: Social_Media_Followers (millions) | F1: Streaming_Plays (millions) | G1: Merchandise_Revenue_Per_Concert (Rs) | H1: Tour_Impact | I1: Cities_Performed_In
A2: Diljit Dosanjh | B2: Punjabi | C2: 2027 | D2: 33738 | E2: 46 | F2: 116 | G2: 22334556 | H2: Yes | I2: Amritsar, Kolkata, Delhi, Mumbai, Bengaluru
A3: Honey Singh | B3: Hip-Hop | C3: 1573 | D3: 35223 | E3: 34 | F3: 430 | G3: 25360560 | H3: No | I3: Pune, Amritsar, Bengaluru
A4: Mika Singh | B4: Bollywood | C4: 1025 | D4: 11057 | E4: 12 | F4: 371 | G4: 7983154 | H4: No | I4: Delhi, Amritsar, Bengaluru, Mumbai
A5: Arijit Singh | B5: Bollywood | C5: 2437 | D5: 25729 | E5: 30 | F5: 584 | G5: 18730712 | H5: Yes | I5: Nagpur, Jaipur, Chandigarh
A6: Ed Sheeran | B6: International Pop | C6: 3436 | D6: 18609 | E6: 55 | F6: 736 | G6: 4856949 | H6: Yes | I6: Pune, Amritsar, Goa, Chandigarh
A7: Bryan Adams | B7: Rock | C7: 992 | E7: 30 | F7: 81 | G7: 8678356 | H7: Yes | I7: Delhi, Jaipur, Bengaluru, Mumbai
A8: DJ Snake | B8: EDM | C8: 1431 | D8: 19089 | E8: 32 | F8: 429 | G8: 10193526 | H8: No | I8: Bengaluru, Jaipur, Mumbai, Chandigarh, Kolkata, Delhi
A9: Martin Garrix | B9: EDM | C9: 2499 | D9: 11603 | E9: 43 | F9: 298 | G9: 6462871 | H9: No | I9: Chandigarh, Delhi, Pune, Nagpur, Bengaluru, Kolkata
A10: Badshah | B10: Bollywood | C10: 3351 | D10: 36448 | E10: 33 | F10: 483 | G10: 20228640 | H10: No | I10: Nagpur, Goa, Amritsar, Chandigarh, Mumbai
A11: Shreya Ghoshal | B11: Classical/Bollywood | C11: 3326 | D11: 3197 | E11: 23 | F11: 271 | G11: 792856 | H11: No | I11: Pune, Mumbai, Delhi, Bengaluru, Amritsar

Sheet Festival_Data_Clean
A1: Festival_Name | B1: City | C1: Date | D1: Tour_Name | E1: Headlining_Artist | F1: Supporting_Artists | G1: Ticket_Price(Rs) | H1: Total_Attendance | I1: Merchandise_Sales (Rs) | J1: Sponsorship_Revenue (Rs) | K1: Total_Revenue (Rs)
A2: NH7 Pune | B2: Kolkata | C2: 45303 | D2: Not Specified | E2: Badshah | F2: DJ Snake, Honey Singh | G2: 1253 | H2: 6166 | I2: 1942290 | J2: 3680408 | K2: 13348696 | P2: =_xlfn.QUARTILE.INC($G$2:$G$101,1) -> 1824
A3: Ziro Festival Arunachal | B3: Delhi | C3: 45403 | D3: Not Specified | E3: Honey Singh | F3: Bryan Adams, Martin Garrix, Mika Singh | G3: 1689 | H3: 40643 | I3: 16622987 | J3: 2589481 | K3: 87858495 | P3: =_xlfn.QUARTILE.INC($G$2:$G$101,3) -> 4045.25
A4: NH7 Pune | B4: Bengaluru | C4: 45553 | D4: Classics Tour | E4: Bryan Adams | F4: Badshah, Arijit Singh, Martin Garrix, Diljit Dosanjh | G4: 6813.8 | H4: 17889.9 | I4: 7667100 | J4: 640053 | K4: 132693072 | P4: =P3-P2 -> 2221.25
A5: VH1 Supersonic Delhi | B5: Goa | C5: 45353 | D5: Not Specified | E5: Honey Singh | F5: Martin Garrix, Badshah, Ed Sheeran, Diljit Dosanjh | G5: 2144 | H5: 14688 | I5: 2350080 | J5: 2712686 | K5: 36553838 | O5: =AVERAGE(H2:H101) -> 21373.119 | P5: =P2-(1.5*P4) -> -1507.875
A6: Hornbill Festival Nagaland | B6: Nagpur | C6: 45454 | D6: Soulful Nights Tour | E6: Arijit Singh | F6: Martin Garrix, Badshah | G6: 1886 | H6: 35244 | I6: 6132456 | J6: 1181193 | K6: 73783833 | P6: =P3+(1.5*P4) -> 7377.125
A7: Ziro Festival Arunachal | B7: Jaipur | C7: 45437 | D7: Not Specified | E7: Mika Singh | F7: Diljit Dosanjh, Mika Singh | G7: 3984 | H7: 31020 | I7: 2252122 | J7: 2302603 | K7: 58605653 | O7: =AVERAGEIFS($H$2:$H$101,$A$2:$A$101,A7,$B$2:$B$101,B7) -> 31020
A8: Ziro Festival Arunachal | B8: Goa | C8: 45371 | D8: Classics Tour | E8: Bryan Adams | F8: Ed Sheeran, Mika Singh, Shreya Ghoshal, Bryan Adams | G8: 1162.4 | H8: 18778.2 | I8: 4828680 | J8: 4948076 | K8: 111635078 | N8: =AVERAGEIFS($G$2:$G$101,$A$2:$A$101,A8,$B$2:$B$101,B8) -> 1162.4 | P8: =_xlfn.QUARTILE.INC($H$2:$H$101,1) -> 11366.6
A9: NH7 Pune | B9: Nagpur | C9: 45462 | D9: Not Specified | E9: Badshah | F9: Honey Singh, Badshah, Bryan Adams, Martin Garrix | G9: 840 | H9: 33535 | I9: 12206740 | J9: 1201595 | K9: 41577735 | P9: =_xlfn.QUARTILE.INC($H$2:$H$101,3) -> 31201.25
A10: Bollywood Music Project | B10: Delhi | C10: 45440 | D10: Not Specified | E10: Shreya Ghoshal | F10: Ed Sheeran, Shreya Ghoshal, Bryan Adams, Badshah | G10: 4191 | H10: 21248.01 | I10: 4279770 | J10: 3427104 | K10: 81824709 | O10: =AVERAGEIFS($H$2:$H$101,$A$2:$A$101,A10,$B$2:$B$101,B10) -> 21248.01 | P10: =P9-P8 -> 19834.65
A11: Lollapalooza Mumbai | B11: Kolkata | C11: 45319 | D11: Not Specified | E11: Honey Singh | F11: Honey Singh, Diljit Dosanjh | G11: 1823 | H11: 15513 | I11: 7539318 | J11: 3948781 | K11: 39768298 | P11: =P8-(1.5*P10) -> -18385.375
A12: Hornbill Festival Nagaland | B12: Jaipur | C12: 45462 | D12: Not Specified | E12: DJ Snake | F12: Honey Singh, Diljit Dosanjh, Arijit Singh | G12: 3953.6 | H12: 21693 | I12: 9306297 | J12: 4798020 | K12: 75365349 | P12: =P9+(1.5*P10) -> 60953.225
A13: Sunburn Goa | B13: Goa | C13: 45649 | D13: Not Specified | E13: Shreya Ghoshal | F13: Honey Singh, Badshah, Bryan Adams | G13: 2842 | H13: 24021 | I13: 5020389 | J13: 2851905 | K13: 76139976
A14: Supersonic Bengaluru | B14: Pune | C14: 45428 | D14: Born To Shine Tour | E14: Diljit Dosanjh | F14: Mika Singh, Ed Sheeran, Arijit Singh | G14: 528 | H14: 33241 | I14: 2659280 | J14: 3167786 | K14: 19328026 | P14: =_xlfn.QUARTILE.INC($I$2:$I$101,1) -> 2706413.8
A15: Magnetic Fields Rajasthan | B15: Mumbai | C15: 45644 | D15: Not Specified | E15: Martin Garrix | F15: Shreya Ghoshal, Ed Sheeran, Arijit Singh | G15: 1543 | H15: 19867 | I15: 2821114 | J15: 2897760 | K15: 36373655 | P15: =_xlfn.QUARTILE.INC($I$2:$I$101,3) -> 7890040
A16: Hornbill Festival Nagaland | B16: Amritsar | C16: 45344 | D16: Not Specified | E16: Shreya Ghoshal | F16: Bryan Adams, Badshah, Honey Singh | G16: 2188 | H16: 20603 | I16: 9559792 | J16: 4600450 | K16: 59239606 | P16: =P15-P14 -> 5183626.2
A17: VH1 Supersonic Delhi | B17: Kolkata | C17: 45581 | D17: Classics Tour | E17: Bryan Adams | F17: Ed Sheeran, Shreya Ghoshal | G17: 2217.6 | H17: 9504.6 | I17: 5892852 | J17: 795307 | K17: 28195711 | P17: =P14-(1.5*P16) -> -5069025.6
A18: Lollapalooza Mumbai | B18: Delhi | C18: 45455 | D18: Classics Tour | E18: Bryan Adams | F18: Martin Garrix, Mika Singh, Bryan Adams | G18: 5397 | H18: 9158.1 | I18: 1687707 | J18: 2188470 | K18: 54311142 | P18: =P15+(1.5*P16) -> 15665479
A19: Ziro Festival Arunachal | B19: Pune | C19: 45384 | D19: Mathematics Tour | E19: Ed Sheeran | F19: Honey Singh, Ed Sheeran | G19: 1601.6 | H19: 11790 | I19: 3030030 | J19: 3635278 | K19: 20153068
A20: Ziro Festival Arunachal | B20: Delhi | C20: 45531 | D20: Not Specified | E20: Shreya Ghoshal | F20: Honey Singh, Mika Singh, Martin Garrix, Ed Sheeran | G20: 4564 | H20: 31755 | I20: 6890835 | J20: 4732974 | K20: 156553629 | P20: =_xlfn.QUARTILE.INC($J$2:$J$101,1) -> 1769087.8
A21: Sunburn Goa | B21: Nagpur | C21: 45634 | D21: Classics Tour | E21: Bryan Adams | F21: Ed Sheeran, Mika Singh, Shreya Ghoshal, Honey Singh | G21: 3350.2 | H21: 2975.7 | I21: 1041495 | J21: 3001940 | K21: 14216078 | P21: =_xlfn.QUARTILE.INC($J$2:$J$101,3) -> 4132571.2
A22: Sunburn Goa | B22: Delhi | C22: 45460 | D22: Not Specified | E22: Badshah | F22: Shreya Ghoshal, Diljit Dosanjh, Arijit Singh | G22: 4045 | H22: 27719 | I22: 7539568 | J22: 4670910 | K22: 124333833 | P22: =P21-P20 -> 2363483.5
A23: Sunburn Goa | B23: Bengaluru | C23: 45425 | D23: Soulful Nights Tour | E23: Arijit Singh | F23: Honey Singh, Diljit Dosanjh, Badshah | G23: 1008 | H23: 21142 | I23: 2558182 | J23: 1632574 | K23: 25501892 | P23: =P20-(1.5*P22) -> -1776137.5
A24: NH7 Pune | B24: Chandigarh | C24: 45474 | D24: Not Specified | E24: Martin Garrix | F24: Honey Singh, Bryan Adams, DJ Snake | G24: 2334 | H24: 16842 | I24: 6905220 | J24: 1067015 | K24: 47281463 | P24: =P21+(1.5*P22) -> 7677796.5
A25: Goa Tribal Festival | B25: Delhi | C25: 45299 | D25: Born To Shine Tour | E25: Diljit Dosanjh | F25: Ed Sheeran, Diljit Dosanjh, Shreya Ghoshal, Badshah | G25: 2930.05 | H25: 14456 | I25: 4603680 | J25: 2403962 | K25: 41090442 | N25: =AVERAGEIFS($G$2:$G$101,$A$2:$A$101,A25,$B$2:$B$101,B25) -> 2930.05
A26: Magnetic Fields Rajasthan | B26: Amritsar | C26: 45416 | D26: Not Specified | E26: Badshah | F26: Mika Singh, Diljit Dosanjh, Martin Garrix | G26: 3977 | H26: 25243 | I26: 9238938 | J26: 4689343 | K26: 114319692 | P26: =_xlfn.QUARTILE.INC($K$2:$K$101,1) -> 29966147
A27: Sunburn Goa | B27: Jaipur | C27: 45407 | D27: Not Specified | E27: Honey Singh | F27: Bryan Adams, Diljit Dosanjh, Honey Singh, Mika Singh | G27: 3449 | H27: 13539 | I27: 5672841 | J27: 3471436 | K27: 55840288 | P27: =_xlfn.QUARTILE.INC($K$2:$K$101,3) -> 94790208
A28: Hornbill Festival Nagaland | B28: Pune | C28: 45316 | D28: Not Specified | E28: Badshah | F28: Martin Garrix, Bryan Adams, DJ Snake | G28: 3668 | H28: 36462 | I28: 5250528 | J28: 2377592 | K28: 141370736 | P28: =P27-P26 -> 64824061
A29: NH7 Pune | B29: Goa | C29: 45539 | D29: Not Specified | E29: Badshah | F29: Arijit Singh, Diljit Dosanjh | G29: 3279 | H29: 32540 | I29: 13341400 | J29: 2840750 | K29: 122880810 | P29: =P26-(1.5*P28) -> -67269945
A30: NH7 Pune | B30: Amritsar | C30: 45639 | D30: Not Specified | E30: Honey Singh | F30: Diljit Dosanjh, Honey Singh, DJ Snake, Shreya Ghoshal | G30: 2948 | H30: 9316 | I30: 1266976 | J30: 2704822 | K30: 31435366 | P30: =P27+(1.5*P28) -> 1.920263e+08
A31: NH7 Pune | B31: Delhi | C31: 45647 | D31: Not Specified | E31: DJ Snake | F31: Bryan Adams, Mika Singh, Arijit Singh | G31: 2749.6 | H31: 17172 | I31: 7830432 | J31: 3956927 | K31: 45513167
A32: Ziro Festival Arunachal | B32: Bengaluru | C32: 45410 | D32: Not Specified | E32: Honey Singh | F32: Arijit Singh, Honey Singh | G32: 4503 | H32: 16737 | I32: 6276375 | J32: 2726932 | K32: 85424449 | N32: =AVERAGEIFS($G$2:$G$101,$A$2:$A$101,A32,$B$2:$B$101,B32) -> 4503 | P32: A column unique & consistency | R32: B col unique & consistency | S32: C col unique & consistency | T32: D col unique & consistency | U32: E col unique & consistency | V32: F col unique & consistency
A33: NH7 Pune | B33: Chandigarh | C33: 45392 | D33: Not Specified | E33: Shreya Ghoshal | F33: Martin Garrix, Diljit Dosanjh, Badshah, Mika Singh | G33: 632 | H33: 35304 | I33: 10379376 | J33: 1590737 | K33: 34282241 | P33: {=_xlfn.UNIQUE(A:A)} -> Festival_Name | R33: {=_xlfn.UNIQUE(B:B)} -> City | S33: {=_xlfn.UNIQUE(C:C)} -> Date | T33: {=_xlfn.UNIQUE(D:D)} -> Tour_Name | U33: {=_xlfn.UNIQUE(E:E)} -> Headlining_Artist | V33: {=_xlfn.UNIQUE(F:F)} -> Supporting_Artists
A34: Goa Tribal Festival | B34: Kolkata | C34: 45360 | D34: Not Specified | E34: Honey Singh | F34: DJ Snake, Arijit Singh, Badshah, Mika Singh | G34: 1932 | H34: 16841 | I34: 7713178 | J34: 4738764 | K34: 44988754 | P34: NH7 Pune | R34: Kolkata | S34: 45303 | T34: Not Specified | U34: Badshah | V34: DJ Snake, Honey Singh
A35: Ziro Festival Arunachal | B35: Goa | C35: 45358 | D35: Classics Tour | E35: Bryan Adams | F35: Mika Singh, Diljit Dosanjh, Shreya Ghoshal | G35: 1598.8 | H35: 18210.5 | I35: 7336230 | J35: 2229062 | K35: 39274422 | P35: Ziro Festival Arunachal | R35: Delhi | S35: 45403 | T35: Classics Tour | U35: Honey Singh | V35: Bryan Adams, Martin Garrix, Mika Singh
A36: NH7 Pune | B36: Delhi | C36: 45326 | D36: Born To Shine Tour | E36: Diljit Dosanjh | F36: Mika Singh, Ed Sheeran, Honey Singh, Diljit Dosanjh | G36: 1933 | H36: 58687.2 | I36: 16296984 | J36: 1120895 | K36: 104681231 | P36: VH1 Supersonic Delhi | R36: Bengaluru | S36: 45553 | T36: Soulful Nights Tour | U36: Bryan Adams | V36: Badshah, Arijit Singh, Martin Garrix, Diljit Dosanjh
A37: Lollapalooza Mumbai | B37: Bengaluru | C37: 45395 | D37: Born To Shine Tour | E37: Diljit Dosanjh | F37: Diljit Dosanjh, DJ Snake, Honey Singh, Shreya Ghoshal | G37: 1824 | H37: 7559.5 | I37: 1913135 | J37: 4680189 | K37: 21654174 | N37: =AVERAGEIFS($G$2:$G$101,$A$2:$A$101,A37,$B$2:$B$101,B37) -> 1824 | P37: Hornbill Festival Nagaland | R37: Goa | S37: 45353 | T37: Born To Shine Tour | U37: Arijit Singh | V37: Martin Garrix, Badshah, Ed Sheeran, Diljit Dosanjh
A38: VH1 Supersonic Delhi | B38: Bengaluru | C38: 45509 | D38: Not Specified | E38: Martin Garrix | F38: DJ Snake, Honey Singh, Diljit Dosanjh | G38: 4452 | H38: 31745 | I38: 4412555 | J38: 4091720 | K38: 149833015 | P38: Bollywood Music Project | R38: Nagpur | S38: 45454 | T38: Mathematics Tour | U38: Mika Singh | V38: Martin Garrix, Badshah
A39: Bollywood Music Project | B39: Mumbai | C39: 45555 | D39: Not Specified | E39: Mika Singh | F39: Arijit Singh, DJ Snake, Martin Garrix | G39: 2716 | H39: 12688 | I39: 2486848 | J39: 1413822 | K39: 38361278 | P39: Lollapalooza Mumbai | R39: Jaipur | S39: 45437 | T39: 0 | U39: Shreya Ghoshal | V39: Diljit Dosanjh, Mika Singh
A40: Sunburn Goa | B40: Chandigarh | C40: 45507 | D40: Not Specified | E40: Mika Singh | F40: DJ Snake, Badshah | G40: 2237 | H40: 20276 | I40: 9671652 | J40: 4912334 | K40: 59941398 | P40: Sunburn Goa | R40: Pune | S40: 45371 | U40: DJ Snake | V40: Ed Sheeran, Mika Singh, Shreya Ghoshal, Bryan Adams
...

Sheet Festival_Clean_PowerBI
A1: Festival_Name | B1: City | C1: Date | D1: Tour_Name | E1: Headlining_Artist | F1: Supporting_Artists | G1: Ticket_Price(Rs) | H1: Total_Attendance | I1: Merchandise_Sales (Rs) | J1: Sponsorship_Revenue (Rs) | K1: Total_Revenue (Rs)
A2: NH7 Pune | B2: Kolkata | C2: 45303 | D2: Not Specified | E2: Badshah | F2: DJ Snake, Honey Singh | G2: 1253 | H2: 6166 | I2: 1942290 | J2: 3680408 | K2: 13348696
A3: Ziro Festival Arunachal | B3: Delhi | C3: 45403 | D3: Not Specified | E3: Honey Singh | F3: Bryan Adams, Martin Garrix, Mika Singh | G3: 1689 | H3: 40643 | I3: 16622987 | J3: 2589481 | K3: 87858495
A4: NH7 Pune | B4: Bengaluru | C4: 45553 | D4: Classics Tour | E4: Bryan Adams | F4: Badshah, Arijit Singh, Martin Garrix, Diljit Dosanjh | G4: 6813.8 | H4: 17889.9 | I4: 7667100 | J4: 640053 | K4: 132693072
A5: VH1 Supersonic Delhi | B5: Goa | C5: 45353 | D5: Not Specified | E5: Honey Singh | F5: Martin Garrix, Badshah, Ed Sheeran, Diljit Dosanjh | G5: 2144 | H5: 14688 | I5: 2350080 | J5: 2712686 | K5: 36553838
A6: Hornbill Festival Nagaland | B6: Nagpur | C6: 45454 | D6: Soulful Nights Tour | E6: Arijit Singh | F6: Martin Garrix, Badshah | G6: 1886 | H6: 35244 | I6: 6132456 | J6: 1181193 | K6: 73783833
A7: Ziro Festival Arunachal | B7: Jaipur | C7: 45437 | D7: Not Specified | E7: Mika Singh | F7: Diljit Dosanjh, Mika Singh | G7: 3984 | H7: 31020 | I7: 2252122 | J7: 2302603 | K7: 58605653
A8: Ziro Festival Arunachal | B8: Goa | C8: 45371 | D8: Classics Tour | E8: Bryan Adams | F8: Ed Sheeran, Mika Singh, Shreya Ghoshal, Bryan Adams | G8: 1162.4 | H8: 18778.2 | I8: 4828680 | J8: 4948076 | K8: 111635078
A9: NH7 Pune | B9: Nagpur | C9: 45462 | D9: Not Specified | E9: Badshah | F9: Honey Singh, Badshah, Bryan Adams, Martin Garrix | G9: 840 | H9: 33535 | I9: 12206740 | J9: 1201595 | K9: 41577735
A10: Bollywood Music Project | B10: Delhi | C10: 45440 | D10: Not Specified | E10: Shreya Ghoshal | F10: Ed Sheeran, Shreya Ghoshal, Bryan Adams, Badshah | G10: 4191 | H10: 21248.01 | I10: 4279770 | J10: 3427104 | K10: 81824709
A11: Lollapalooza Mumbai | B11: Kolkata | C11: 45319 | D11: Not Specified | E11: Honey Singh | F11: Honey Singh, Diljit Dosanjh | G11: 1823 | H11: 15513 | I11: 7539318 | J11: 3948781 | K11: 39768298
A12: Hornbill Festival Nagaland | B12: Jaipur | C12: 45462 | D12: Not Specified | E12: DJ Snake | F12: Honey Singh, Diljit Dosanjh, Arijit Singh | G12: 3953.6 | H12: 21693 | I12: 9306297 | J12: 4798020 | K12: 75365349
A13: Sunburn Goa | B13: Goa | C13: 45649 | D13: Not Specified | E13: Shreya Ghoshal | F13: Honey Singh, Badshah, Bryan Adams | G13: 2842 | H13: 24021 | I13: 5020389 | J13: 2851905 | K13: 76139976
... A101: Ziro Festival Arunachal | B101: Goa | C101: 45499 | D101: Not Specified | E101: Mika Singh | F101: Shreya Ghoshal, Honey Singh, Badshah | G101: 726 | H101: 37105 | I101: 14545160 | J101: 835232 | K101: 42318622

Sheet Artist_Popularity_Clean
A1: Artist_Name | B1: Genre | C1: Average_Ticket_Price | D1: Average_Attendance_Per_City | E1: Social_Media_Followers (millions) | F1: Streaming_Plays (millions) | G1: Merchandise_Revenue_Per_Concert (Rs) | H1: Tour_Impact | I1: Cities_Performed_In
A2: Diljit Dosanjh | B2: Punjabi | C2: 2027 | D2: 33738 | E2: 46 | F2: 116 | G2: 22334556 | H2: Yes | I2: Amritsar, Kolkata, Delhi, Mumbai, Bengaluru
A3: Honey Singh | B3: Hip-Hop | C3: 1573 | D3: 35223 | E3: 34 | F3: 430 | G3: 25360560 | H3: No | I3: Pune, Amritsar, Bengaluru
A4: Mika Singh | B4: Bollywood | C4: 1025 | D4: 11057 | E4: 12 | F4: 371 | G4: 7983154 | H4: No | I4: Delhi, Amritsar, Bengaluru, Mumbai
A5: Arijit Singh | B5: Bollywood | C5: 2437 | D5: 25729 | E5: 30 | F5: 584 | G5: 18730712 | H5: Yes | I5: Nagpur, Jaipur, Chandigarh
A6: Ed Sheeran | B6: International Pop | C6: 3436 | D6: 18609 | E6: 55 | F6: 736 | G6: 4856949 | H6: Yes | I6: Pune, Amritsar, Goa, Chandigarh
A7: Bryan Adams | B7: Rock | C7: 992 | D7: 21632.556 | E7: 30 | F7: 81 | G7: 8678356 | H7: Yes | I7: Delhi, Jaipur, Bengaluru, Mumbai
A8: DJ Snake | B8: EDM | C8: 1431 | D8: 19089 | E8: 32 | F8: 429 | G8: 10193526 | H8: No | I8: Bengaluru, Jaipur, Mumbai, Chandigarh, Kolkata, Delhi
A9: Martin Garrix | B9: EDM | C9: 2499 | D9: 11603 | E9: 43 | F9: 298 | G9: 6462871 | H9: No | I9: Chandigarh, Delhi, Pune, Nagpur, Bengaluru, Kolkata
A10: Badshah | B10: Bollywood | C10: 3351 | D10: 36448 | E10: 33 | F10: 483 | G10: 20228640 | H10: No | I10: Nagpur, Goa, Amritsar, Chandigarh, Mumbai
A11: Shreya Ghoshal | B11: Classical/Bollywood | C11: 3326 | D11: 3197 | E11: 23 | F11: 271 | G11: 792856 | H11: No | I11: Pune, Mumbai, Delhi, Bengaluru, Amritsar
C14: Outlier | D14: Outlier | E14: Outlier | F14: Outlier | G14: Outlier
C15: =_xlfn.QUARTILE.INC($C$2:$C$11,1) -> 1466.5 | D15: =_xlfn.QUARTILE.INC($D$2:$D$11,1) -> 13354.5 | E15: =_xlfn.QUARTILE.INC($E$2:$E$11,1) -> 30 | F15: =_xlfn.QUARTILE.INC($F$2:$F$11,1) -> 277.75 | G15: =_xlfn.QUARTILE.INC($G$2:$G$11,1) -> 6842941.8
C16: =_xlfn.QUARTILE.INC($C$2:$C$11,3) -> 3119.25 | D16: =_xlfn.QUARTILE.INC($D$2:$D$11,3) -> 31735.75 | E16: =_xlfn.QUARTILE.INC($E$2:$E$11,3) -> 40.75 | F16: =_xlfn.QUARTILE.INC($F$2:$F$11,3) -> 469.75 | G16: =_xlfn.QUARTILE.INC($G$2:$G$11,3) -> 19854158
C17: =C16-C15 -> 1652.75 | D17: =D16-D15 -> 18381.25 | E17: =E16-E15 -> 10.75 | F17: =F16-F15 -> 192 | G17: =G16-G15 -> 13011216
C18: =C15-(1.5*C17) -> -1012.625 | D18: =D15-(1.5*D17) -> -14217.375 | E18: =E15-(1.5*E17) -> 13.875 | F18: =F15-(1.5*F17) -> -10.25 | G18: =G15-(1.5*G17) -> -12673883
C19: =C16+(1.5*C17) -> 5598.375 | D19: =D16+(1.5*D17) -> 59307.625 | E19: =E16+(1.5*E17) -> 56.875 | F19: =F16+(1.5*F17) -> 757.75 | G19: =G16+(1.5*G17) -> 39370982

Sheet Artist_Popularity_Clean_PowerBI
A1: Artist_Name | B1: Genre | C1: Average_Ticket_Price | D1: Average_Attendance_Per_City | E1: Social_Media_Followers (millions) | F1: Streaming_Plays (millions) | G1: Merchandise_Revenue_Per_Concert (Rs) | H1: Tour_Impact | I1: Cities_Performed_In
A2: Diljit Dosanjh | B2: Punjabi | C2: 2027 | D2: 33738 | E2: 46 | F2: 116 | G2: 22334556 | H2: Yes | I2: Amritsar, Kolkata, Delhi, Mumbai, Bengaluru
A3: Honey Singh | B3: Hip-Hop | C3: 1573 | D3: 35223 | E3: 34 | F3: 430 | G3: 25360560 | H3: No | I3: Pune, Amritsar, Bengaluru
A4: Mika Singh | B4: Bollywood | C4: 1025 | D4: 11057 | E4: 12 | F4: 371 | G4: 7983154 | H4: No | I4: Delhi, Amritsar, Bengaluru, Mumbai
A5: Arijit Singh | B5: Bollywood | C5: 2437 | D5: 25729 | E5: 30 | F5: 584 | G5: 18730712 | H5: Yes | I5: Nagpur, Jaipur, Chandigarh
A6: Ed Sheeran | B6: International Pop | C6: 3436 | D6: 18609 | E6: 55 | F6: 736 | G6: 4856949 | H6: Yes | I6: Pune, Amritsar, Goa, Chandigarh
A7: Bryan Adams | B7: Rock | C7: 992 | D7: 21632.556 | E7: 30 | F7: 81 | G7: 8678356 | H7: Yes | I7: Delhi, Jaipur, Bengaluru, Mumbai
A8: DJ Snake | B8: EDM | C8: 1431 | D8: 19089 | E8: 32 | F8: 429 | G8: 10193526 | H8: No | I8: Bengaluru, Jaipur, Mumbai, Chandigarh, Kolkata, Delhi
A9: Martin Garrix | B9: EDM | C9: 2499 | D9: 11603 | E9: 43 | F9: 298 | G9: 6462871 | H9: No | I9: Chandigarh, Delhi, Pune, Nagpur, Bengaluru, Kolkata
A10: Badshah | B10: Bollywood | C10: 3351 | D10: 36448 | E10: 33 | F10: 483 | G10: 20228640 | H10: No | I10: Nagpur, Goa, Amritsar, Chandigarh, Mumbai
A11: Shreya Ghoshal | B11: Classical/Bollywood | C11: 3326 | D11: 3197 | E11: 23 | F11: 271 | G11: 792856 | H11: No | I11: Pune, Mumbai, Delhi, Bengaluru, Amritsar

Sheet Stage2_Q1
A1: Months | B1: Total Attendance | D1: Month | E1: Total Attendance | F1: Festival Count | J1: Peak Month
A2: =TEXT(Festival_Data_Clean!C2,"mmmm") -> January | B2: =SUMIF(A$2:A$101,A2,Festival_Data_Clean!H$2:H$101) -> 183383.5 | D2: {=_xlfn.UNIQUE(A2:A101)} -> January | E2: {=_xlfn.UNIQUE(B2:B101)} -> 183383.5 | F2: =COUNTIF($A$2:$A$101,D2) -> 9 | J2: =MAX(E2:E13) -> 288400.9
A3: =TEXT(Festival_Data_Clean!C3,"mmmm") -> April | B3: =SUMIF(A$2:A$101,A3,Festival_Data_Clean!H$2:H$101) -> 185700.6 | D3: April | E3: 185700.6 | F3: =COUNTIF($A$2:$A$101,D3) -> 9
A4: =TEXT(Festival_Data_Clean!C4,"mmmm") -> September | B4: =SUMIF(A$2:A$101,A4,Festival_Data_Clean!H$2:H$101) -> 142573 | D4: September | E4: 142573 | F4: =COUNTIF($A$2:$A$101,D4) -> 6
A5: =TEXT(Festival_Data_Clean!C5,"mmmm") -> March | B5: =SUMIF(A$2:A$101,A5,Festival_Data_Clean!H$2:H$101) -> 99290.7 | D5: March | E5: 99290.7 | F5: =COUNTIF($A$2:$A$101,D5) -> 7
A6: =TEXT(Festival_Data_Clean!C6,"mmmm") -> June | B6: =SUMIF(A$2:A$101,A6,Festival_Data_Clean!H$2:H$101) -> 216292.12 | D6: June | E6: 216292.12 | F6: =COUNTIF($A$2:$A$101,D6) -> 10
A7: =TEXT(Festival_Data_Clean!C7,"mmmm") -> May | B7: =SUMIF(A$2:A$101,A7,Festival_Data_Clean!H$2:H$101) -> 206816.01 | D7: May | E7: 206816.01 | F7: =COUNTIF($A$2:$A$101,D7) -> 11
A8: =TEXT(Festival_Data_Clean!C8,"mmmm") -> March | B8: =SUMIF(A$2:A$101,A8,Festival_Data_Clean!H$2:H$101) -> 99290.7 | D8: December | E8: 261513.71 | F8: =COUNTIF($A$2:$A$101,D8) -> 12
A9: =TEXT(Festival_Data_Clean!C9,"mmmm") -> June | B9: =SUMIF(A$2:A$101,A9,Festival_Data_Clean!H$2:H$101) -> 216292.12 | D9: February | E9: 154615.3 | F9: =COUNTIF($A$2:$A$101,D9) -> 8
A10: =TEXT(Festival_Data_Clean!C10,"mmmm") -> May | B10: =SUMIF(A$2:A$101,A10,Festival_Data_Clean!H$2:H$101) -> 206816.01 | D10: October | E10: 29962.6 | F10: =COUNTIF($A$2:$A$101,D10) -> 3
A11: =TEXT(Festival_Data_Clean!C11,"mmmm") -> January | B11: =SUMIF(A$2:A$101,A11,Festival_Data_Clean!H$2:H$101) -> 183383.5 | D11: August | E11: 288400.9 | F11: =COUNTIF($A$2:$A$101,D11) -> 12
A12: =TEXT(Festival_Data_Clean!C12,"mmmm") -> June | B12: =SUMIF(A$2:A$101,A12,Festival_Data_Clean!H$2:H$101) -> 216292.12 | D12: July | E12: 158221.6 | F12: =COUNTIF($A$2:$A$101,D12) -> 6
A13: =TEXT(Festival_Data_Clean!C13,"mmmm") -> December | B13: =SUMIF(A$2:A$101,A13,Festival_Data_Clean!H$2:H$101) -> 261513.71 | D13: November | E13: 210541.82 | F13: =COUNTIF($A$2:$A$101,D13) -> 7
A14: =TEXT(Festival_Data_Clean!C14,"mmmm") -> May | B14: =SUMIF(A$2:A$101,A14,Festival_Data_Clean!H$2:H$101) -> 206816.01
A15: =TEXT(Festival_Data_Clean!C15,"mmmm") -> December | B15: =SUMIF(A$2:A$101,A15,Festival_Data_Clean!H$2:H$101) -> 261513.71
A16: =TEXT(Festival_Data_Clean!C16,"mmmm") -> February | B16: =SUMIF(A$2:A$101,A16,Festival_Data_Clean!H$2:H$101) -> 154615.3
A17: =TEXT(Festival_Data_Clean!C17,"mmmm") -> October | B17: =SUMIF(A$2:A$101,A17,Festival_Data_Clean!H$2:H$101) -> 29962.6
A18: =TEXT(Festival_Data_Clean!C18,"mmmm") -> June | B18: =SUMIF(A$2:A$101,A18,Festival_Data_Clean!H$2:H$101) -> 216292.12
A19: =TEXT(Festival_Data_Clean!C19,"mmmm") -> April | B19: =SUMIF(A$2:A$101,A19,Festival_Data_Clean!H$2:H$101) -> 185700.6
A20: =TEXT(Festival_Data_Clean!C20,"mmmm") -> August | B20: =SUMIF(A$2:A$101,A20,Festival_Data_Clean!H$2:H$101) -> 288400.9
A21: =TEXT(Festival_Data_Clean!C21,"mmmm") -> December | B21: =SUMIF(A$2:A$101,A21,Festival_Data_Clean!H$2:H$101) -> 261513.71
A22: =TEXT(Festival_Data_Clean!C22,"mmmm") -> June | B22: =SUMIF(A$2:A$101,A22,Festival_Data_Clean!H$2:H$101) -> 216292.12
A23: =TEXT(Festival_Data_Clean!C23,"mmmm") -> May | B23: =SUMIF(A$2:A$101,A23,Festival_Data_Clean!H$2:H$101) -> 206816.01
A24: =TEXT(Festival_Data_Clean!C24,"mmmm") -> July | B24: =SUMIF(A$2:A$101,A24,Festival_Data_Clean!H$2:H$101) -> 158221.6
A25: =TEXT(Festival_Data_Clean!C25,"mmmm") -> January | B25: =SUMIF(A$2:A$101,A25,Festival_Data_Clean!H$2:H$101) -> 183383.5
... A101: =TEXT(Festival_Data_Clean!C101,"mmmm") -> July | B101: =SUMIF(A$2:A$101,A101,Festival_Data_Clean!H$2:H$101) -> 158221.6

Sheet Stage2_Q2
A1: City | B1: Total Attendance | C1: Festival Count | E1: Top City | G1: City | H1: Total Attendance | I1: Festival Count
A2: {=_xlfn.UNIQUE(Festival_Data_Clean!B2:B101)} -> Kolkata | B2: =SUMIF(Festival_Data_Clean!B$2:B$101,A2,Festival_Data_Clean!H$2:H$101) -> 144910.2 | C2: =COUNTIF(Festival_Data_Clean!B$2:B$101,A2) -> 8 | E2: =INDEX(A2:A11,MATCH(MAX(B2:B11),B2:B11,0)) -> Goa | G2: {=_xlfn.SORTBY(A2:C11,B2:B11,-1)} -> Goa | H2: 382152.11 | I2: 16
A3: Delhi | B3: =SUMIF(Festival_Data_Clean!B$2:B$101,A3,Festival_Data_Clean!H$2:H$101) -> 280485.41 | C3: =COUNTIF(Festival_Data_Clean!B$2:B$101,A3) -> 12 | G3: Jaipur | H3: 334965.9 | I3: 13
A4: Bengaluru | B4: =SUMIF(Festival_Data_Clean!B$2:B$101,A4,Festival_Data_Clean!H$2:H$101) -> 150796.4 | C4: =COUNTIF(Festival_Data_Clean!B$2:B$101,A4) -> 10 | G4: Nagpur | H4: 310677.22 | I4: 14
A5: Goa | B5: =SUMIF(Festival_Data_Clean!B$2:B$101,A5,Festival_Data_Clean!H$2:H$101) -> 382152.11 | C5: =COUNTIF(Festival_Data_Clean!B$2:B$101,A5) -> 16 | G5: Delhi | H5: 280485.41 | I5: 12
A6: Nagpur | B6: =SUMIF(Festival_Data_Clean!B$2:B$101,A6,Festival_Data_Clean!H$2:H$101) -> 310677.22 | C6: =COUNTIF(Festival_Data_Clean!B$2:B$101,A6) -> 14 | G6: Pune | H6: 182282.2 | I6: 8
A7: Jaipur | B7: =SUMIF(Festival_Data_Clean!B$2:B$101,A7,Festival_Data_Clean!H$2:H$101) -> 334965.9 | C7: =COUNTIF(Festival_Data_Clean!B$2:B$101,A7) -> 13 | G7: Chandigarh | H7: 155236.1 | I7: 8
A8: Pune | B8: =SUMIF(Festival_Data_Clean!B$2:B$101,A8,Festival_Data_Clean!H$2:H$101) -> 182282.2 | C8: =COUNTIF(Festival_Data_Clean!B$2:B$101,A8) -> 8 | G8: Bengaluru | H8: 150796.4 | I8: 10
A9: Mumbai | B9: =SUMIF(Festival_Data_Clean!B$2:B$101,A9,Festival_Data_Clean!H$2:H$101) -> 79127.2 | C9: =COUNTIF(Festival_Data_Clean!B$2:B$101,A9) -> 5 | G9: Kolkata | H9: 144910.2 | I9: 8
A10: Amritsar | B10: =SUMIF(Festival_Data_Clean!B$2:B$101,A10,Festival_Data_Clean!H$2:H$101) -> 116679.12 | C10: =COUNTIF(Festival_Data_Clean!B$2:B$101,A10) -> 6 | G10: Amritsar | H10: 116679.12 | I10: 6
A11: Chandigarh | B11: =SUMIF(Festival_Data_Clean!B$2:B$101,A11,Festival_Data_Clean!H$2:H$101) -> 155236.1 | C11: =COUNTIF(Festival_Data_Clean!B$2:B$101,A11) -> 8 | G11: Mumbai | H11: 79127.2 | I11: 5

Sheet Stage2_Q3
A1: Headlining Artist | B1: Total Attendance | C1: Atrist Type | E1: Artist Type | F1: Total Attendance | G1: Attendance Share %
A2: {=_xlfn.UNIQUE(Festival_Data_Clean!E2:E101)} -> Badshah | B2: =SUMIF(Festival_Data_Clean!E$2:E$101,A2,Festival_Data_Clean!H$2:H$101) -> 260001.01 | C2: Local | E2: Local | F2: =SUMIF($C$2:$C$11,E2,$B$2:$B$11) -> 1557694.1 | G2: =F2/SUM($F$2:$F$3) -> 0.72880994
A3: Honey Singh | B3: =SUMIF(Festival_Data_Clean!E$2:E$101,A3,Festival_Data_Clean!H$2:H$101) -> 250955 | C3: Local | E3: International | F3: =SUMIF($C$2:$C$11,E3,$B$2:$B$11) -> 579617.73 | G3: =F3/SUM($F$2:$F$3) -> 0.27119006
A4: Bryan Adams | B4: =SUMIF(Festival_Data_Clean!E$2:E$101,A4,Festival_Data_Clean!H$2:H$101) -> 195282.71 | C4: International
A5: Arijit Singh | B5: =SUMIF(Festival_Data_Clean!E$2:E$101,A5,Festival_Data_Clean!H$2:H$101) -> 230409.6 | C5: Local
A6: Mika Singh | B6: =SUMIF(Festival_Data_Clean!E$2:E$101,A6,Festival_Data_Clean!H$2:H$101) -> 242754 | C6: Local
A7: Shreya Ghoshal | B7: =SUMIF(Festival_Data_Clean!E$2:E$101,A7,Festival_Data_Clean!H$2:H$101) -> 210142.62 | C7: Local
A8: DJ Snake | B8: =SUMIF(Festival_Data_Clean!E$2:E$101,A8,Festival_Data_Clean!H$2:H$101) -> 168650.01 | C8: International
A9: Diljit Dosanjh | B9: =SUMIF(Festival_Data_Clean!E$2:E$101,A9,Festival_Data_Clean!H$2:H$101) -> 363431.9 | C9: Local
A10: Martin Garrix | B10: =SUMIF(Festival_Data_Clean!E$2:E$101,A10,Festival_Data_Clean!H$2:H$101) -> 116336 | C10: International
A11: Ed Sheeran | B11: =SUMIF(Festival_Data_Clean!E$2:E$101,A11,Festival_Data_Clean!H$2:H$101) -> 99349.01 | C11: International

Sheet Stage3_Q1
A1: City | B1: Avg Ticket Price | C1: Avg Attendance | E1: Price-Attendance Correlation
A2: {=_xlfn.UNIQUE(Festival_Data_Clean!B2:B101)} -> Kolkata | B2: =AVERAGEIF(Festival_Data_Clean!$B$2:$B$101,A2,Festival_Data_Clean!$G$2:$G$101) -> 2832.2 | C2: =AVERAGEIF(Festival_Data_Clean!$B$2:$B$101,A2,Festival_Data_Clean!$H$2:$H$101) -> 18113.775 | E2: =CORREL(B2:B11,C2:C11) -> 0.13408749
A3: Delhi | B3: =AVERAGEIF(Festival_Data_Clean!$B$2:$B$101,A3,Festival_Data_Clean!$G$2:$G$101) -> 4060.8875 | C3: =AVERAGEIF(Festival_Data_Clean!$B$2:$B$101,A3,Festival_Data_Clean!$H$2:$H$101) -> 23373.784
A4: Bengaluru | B4: =AVERAGEIF(Festival_Data_Clean!$B$2:$B$101,A4,Festival_Data_Clean!$G$2:$G$101) -> 3754.8 | C4: =AVERAGEIF(Festival_Data_Clean!$B$2:$B$101,A4,Festival_Data_Clean!$H$2:$H$101) -> 15079.64
A5: Goa | B5: =AVERAGEIF(Festival_Data_Clean!$B$2:$B$101,A5,Festival_Data_Clean!$G$2:$G$101) -> 2439.6406 | C5: =AVERAGEIF(Festival_Data_Clean!$B$2:$B$101,A5,Festival_Data_Clean!$H$2:$H$101) -> 23884.507
A6: Nagpur | B6: =AVERAGEIF(Festival_Data_Clean!$B$2:$B$101,A6,Festival_Data_Clean!$G$2:$G$101) -> 2663.1 | C6: =AVERAGEIF(Festival_Data_Clean!$B$2:$B$101,A6,Festival_Data_Clean!$H$2:$H$101) -> 22191.23
A7: Jaipur | B7: =AVERAGEIF(Festival_Data_Clean!$B$2:$B$101,A7,Festival_Data_Clean!$G$2:$G$101) -> 3183.3385 | C7: =AVERAGEIF(Festival_Data_Clean!$B$2:$B$101,A7,Festival_Data_Clean!$H$2:$H$101) -> 25766.608
A8: Pune | B8: =AVERAGEIF(Festival_Data_Clean!$B$2:$B$101,A8,Festival_Data_Clean!$G$2:$G$101) -> 3479.1 | C8: =AVERAGEIF(Festival_Data_Clean!$B$2:$B$101,A8,Festival_Data_Clean!$H$2:$H$101) -> 22785.275
A9: Mumbai | B9: =AVERAGEIF(Festival_Data_Clean!$B$2:$B$101,A9,Festival_Data_Clean!$G$2:$G$101) -> 2489.6 | C9: =AVERAGEIF(Festival_Data_Clean!$B$2:$B$101,A9,Festival_Data_Clean!$H$2:$H$101) -> 15825.44
A10: Amritsar | B10: =AVERAGEIF(Festival_Data_Clean!$B$2:$B$101,A10,Festival_Data_Clean!$G$2:$G$101) -> 2686.6667 | C10: =AVERAGEIF(Festival_Data_Clean!$B$2:$B$101,A10,Festival_Data_Clean!$H$2:$H$101) -> 19446.52
A11: Chandigarh | B11: =AVERAGEIF(Festival_Data_Clean!$B$2:$B$101,A11,Festival_Data_Clean!$G$2:$G$101) -> 2033.9 | C11: =AVERAGEIF(Festival_Data_Clean!$B$2:$B$101,A11,Festival_Data_Clean!$H$2:$H$101) -> 19404.513

Sheet Stage3_Q2
A1: Festival | B1: Ticket Price | C1: Attendance | D1: Total Revenue | E1: Price Range | G1: Price Range | H1: Total Attendance | J1: Price Range | K1: Total Revenue | M1: Price Range | N1: Avg Revenue/Festival | P1: Price Range | Q1: Avg Attendance/Festival
A2: =Festival_Data_Clean!A2 -> NH7 Pune | B2: =Festival_Data_Clean!G2 -> 1253 | C2: =Festival_Data_Clean!H2 -> 6166 | D2: =Festival_Data_Clean!K2 -> 13348696 | E2: =IF(B2<=1500,"₹0-1,500",IF(B2<=3000,"₹1,501-3,000",IF(B2<=4500,"₹3,001-4,500","₹4,500+"))) -> ₹0-1,500 | G2: {=_xlfn.UNIQUE(E2:E101)} -> ₹0-1,500 | H2: =SUMIF($E$2:$E$101,G2,$C$2:$C$101) -> 444702.82 | J2: {=_xlfn.UNIQUE(E2:E101)} -> ₹0-1,500 | K2: =SUMIF($E$2:$E$101,J2,$D$2:$D$101) -> 622941770 | M2: =J2 -> ₹0-1,500 | N2: =K2/COUNTIF($E$2:$E$101,M2) -> 36643634 | P2: =G2 -> ₹0-1,500 | Q2: =H2/COUNTIF($E$2:$E$101,P2) -> 26158.989
A3: =Festival_Data_Clean!A3 -> Ziro Festival Arunachal | B3: =Festival_Data_Clean!G3 -> 1689 | C3: =Festival_Data_Clean!H3 -> 40643 | D3: =Festival_Data_Clean!K3 -> 87858495 | E3: =IF(B3<=1500,"₹0-1,500",IF(B3<=3000,"₹1,501-3,000",IF(B3<=4500,"₹3,001-4,500","₹4,500+"))) -> ₹1,501-3,000 | G3: ₹1,501-3,000 | H3: =SUMIF($E$2:$E$101,G3,$C$2:$C$101) -> 732707.43 | J3: ₹1,501-3,000 | K3: =SUMIF($E$2:$E$101,J3,$D$2:$D$101) -> 2064396533 | M3: =J3 -> ₹1,501-3,000 | N3: =K3/COUNTIF($E$2:$E$101,M3) -> 55794501 | P3: =G3 -> ₹1,501-3,000 | Q3: =H3/COUNTIF($E$2:$E$101,P3) -> 19802.904
A4: =Festival_Data_Clean!A4 -> NH7 Pune | B4: =Festival_Data_Clean!G4 -> 6813.8 | C4: =Festival_Data_Clean!H4 -> 17889.9 | D4: =Festival_Data_Clean!K4 -> 132693072 | E4: =IF(B4<=1500,"₹0-1,500",IF(B4<=3000,"₹1,501-3,000",IF(B4<=4500,"₹3,001-4,500","₹4,500+"))) -> ₹4,500+ | G4: ₹4,500+ | H4: =SUMIF($E$2:$E$101,G4,$C$2:$C$101) -> 244046.9 | J4: ₹4,500+ | K4: =SUMIF($E$2:$E$101,J4,$D$2:$D$101) -> 1490524812 | M4: =J4 -> ₹4,500+ | N4: =K4/COUNTIF($E$2:$E$101,M4) -> 99368321 | P4: =G4 -> ₹4,500+ | Q4: =H4/COUNTIF($E$2:$E$101,P4) -> 16269.793
A5: =Festival_Data_Clean!A5 -> VH1 Supersonic Delhi | B5: =Festival_Data_Clean!G5 -> 2144 | C5: =Festival_Data_Clean!H5 -> 14688 | D5: =Festival_Data_Clean!K5 -> 36553838 | E5: =IF(B5<=1500,"₹0-1,500",IF(B5<=3000,"₹1,501-3,000",IF(B5<=4500,"₹3,001-4,500","₹4,500+"))) -> ₹1,501-3,000 | G5: ₹3,001-4,500 | H5: =SUMIF($E$2:$E$101,G5,$C$2:$C$101) -> 715854.71 | J5: ₹3,001-4,500 | K5: =SUMIF($E$2:$E$101,J5,$D$2:$D$101) -> 2757866523 | M5: =J5 -> ₹3,001-4,500 | N5: =K5/COUNTIF($E$2:$E$101,M5) -> 88963436 | P5: =G5 -> ₹3,001-4,500 | Q5: =H5/COUNTIF($E$2:$E$101,P5) -> 23092.087
A6: =Festival_Data_Clean!A6 -> Hornbill Festival Nagaland | B6: =Festival_Data_Clean!G6 -> 1886 | C6: =Festival_Data_Clean!H6 -> 35244 | D6: =Festival_Data_Clean!K6 -> 73783833 | E6: =IF(B6<=1500,"₹0-1,500",IF(B6<=3000,"₹1,501-3,000",IF(B6<=4500,"₹3,001-4,500","₹4,500+"))) -> ₹1,501-3,000
A7: =Festival_Data_Clean!A7 -> Ziro Festival Arunachal | B7: =Festival_Data_Clean!G7 -> 3984 | C7: =Festival_Data_Clean!H7 -> 31020 | D7: =Festival_Data_Clean!K7 -> 58605653 | E7: =IF(B7<=1500,"₹0-1,500",IF(B7<=3000,"₹1,501-3,000",IF(B7<=4500,"₹3,001-4,500","₹4,500+"))) -> ₹3,001-4,500
A8: =Festival_Data_Clean!A8 -> Ziro Festival Arunachal | B8: =Festival_Data_Clean!G8 -> 1162.4 | C8: =Festival_Data_Clean!H8 -> 18778.2 | D8: =Festival_Data_Clean!K8 -> 111635078 | E8: =IF(B8<=1500,"₹0-1,500",IF(B8<=3000,"₹1,501-3,000",IF(B8<=4500,"₹3,001-4,500","₹4,500+"))) -> ₹0-1,500
A9: =Festival_Data_Clean!A9 -> NH7 Pune | B9: =Festival_Data_Clean!G9 -> 840 | C9: =Festival_Data_Clean!H9 -> 33535 | D9: =Festival_Data_Clean!K9 -> 41577735 | E9: =IF(B9<=1500,"₹0-1,500",IF(B9<=3000,"₹1,501-3,000",IF(B9<=4500,"₹3,001-4,500","₹4,500+"))) -> ₹0-1,500
A10: =Festival_Data_Clean!A10 -> Bollywood Music Project | B10: =Festival_Data_Clean!G10 -> 4191 | C10: =Festival_Data_Clean!H10 -> 21248.01 | D10: =Festival_Data_Clean!K10 -> 81824709 | E10: =IF(B10<=1500,"₹0-1,500",IF(B10<=3000,"₹1,501-3,000",IF(B10<=4500,"₹3,001-4,500","₹4,500+"))) -> ₹3,001-4,500
A11: =Festival_Data_Clean!A11 -> Lollapalooza Mumbai | B11: =Festival_Data_Clean!G11 -> 1823 | C11: =Festival_Data_Clean!H11 -> 15513 | D11: =Festival_Data_Clean!K11 -> 39768298 | E11: =IF(B11<=1500,"₹0-1,500",IF(B11<=3000,"₹1,501-3,000",IF(B11<=4500,"₹3,001-4,500","₹4,500+"))) -> ₹1,501-3,000
A12: =Festival_Data_Clean!A12 -> Hornbill Festival Nagaland | B12: =Festival_Data_Clean!G12 -> 3953.6 | C12: =Festival_Data_Clean!H12 -> 21693 | D12: =Festival_Data_Clean!K12 -> 75365349 | E12: =IF(B12<=1500,"₹0-1,500",IF(B12<=3000,"₹1,501-3,000",IF(B12<=4500,"₹3,001-4,500","₹4,500+"))) -> ₹3,001-4,500
A13: =Festival_Data_Clean!A13 -> Sunburn Goa | B13: =Festival_Data_Clean!G13 -> 2842 | C13: =Festival_Data_Clean!H13 -> 24021 | D13: =Festival_Data_Clean!K13 -> 76139976 | E13: =IF(B13<=1500,"₹0-1,500",IF(B13<=3000,"₹1,501-3,000",IF(B13<=4500,"₹3,001-4,500","₹4,500+"))) -> ₹1,501-3,000
A14: =Festival_Data_Clean!A14 -> Supersonic Bengaluru | B14: =Festival_Data_Clean!G14 -> 528 | C14: =Festival_Data_Clean!H14 -> 33241 | D14: =Festival_Data_Clean!K14 -> 19328026 | E14: =IF(B14<=1500,"₹0-1,500",IF(B14<=3000,"₹1,501-3,000",IF(B14<=4500,"₹3,001-4,500","₹4,500+"))) -> ₹0-1,500
A15: =Festival_Data_Clean!A15 -> Magnetic Fields Rajasthan | B15: =Festival_Data_Clean!G15 -> 1543 | C15: =Festival_Data_Clean!H15 -> 19867 | D15: =Festival_Data_Clean!K15 -> 36373655 | E15: =IF(B15<=1500,"₹0-1,500",IF(B15<=3000,"₹1,501-3,000",IF(B15<=4500,"₹3,001-4,500","₹4,500+"))) -> ₹1,501-3,000
A16: =Festival_Data_Clean!A16 -> Hornbill Festival Nagaland | B16: =Festival_Data_Clean!G16 -> 2188 | C16: =Festival_Data_Clean!H16 -> 20603 | D16: =Festival_Data_Clean!K16 -> 59239606 | E16: =IF(B16<=1500,"₹0-1,500",IF(B16<=3000,"₹1,501-3,000",IF(B16<=4500,"₹3,001-4,500","₹4,500+"))) -> ₹1,501-3,000
A17: =Festival_Data_Clean!A17 -> VH1 Supersonic Delhi | B17: =Festival_Data_Clean!G17 -> 2217.6 | C17: =Festival_Data_Clean!H17 -> 9504.6 | D17: =Festival_Data_Clean!K17 -> 28195711 | E17: =IF(B17<=1500,"₹0-1,500",IF(B17<=3000,"₹1,501-3,000",IF(B17<=4500,"₹3,001-4,500","₹4,500+"))) -> ₹1,501-3,000
... A101: =Festival_Data_Clean!A101 -> Ziro Festival Arunachal | B101: =Festival_Data_Clean!G101 -> 726 | C101: =Festival_Data_Clean!H101 -> 37105 | D101: =Festival_Data_Clean!K101 -> 42318622 | E101: =IF(B101<=1500,"₹0-1,500",IF(B101<=3000,"₹1,501-3,000",IF(B101<=4500,"₹3,001-4,500","₹4,500+"))) -> ₹0-1,500

Sheet Stage3_Q3
A1: Festival | B1: Min Ticket Price | C1: Max Ticket Price | D1: Price Variation | F1: Price Variation Observed | H1: Price Variation Status | I1: Festival Count
A2: {=_xlfn.UNIQUE(Festival_Data_Clean!A2:A101)} -> NH7 Pune | B2: =_xlfn.MINIFS(Festival_Data_Clean!$G$2:$G$101,Festival_Data_Clean!$A$2:$A$101,A2) -> 632 | C2: =_xlfn.MAXIFS(Festival_Data_Clean!$G$2:$G$101,Festival_Data_Clean!$A$2:$A$101,A2) -> 6914.6 | D2: =C2-B2 -> 6282.6 | F2: =IF(D2>0,"Yes","No") -> Yes | H2: Yes | I2: =COUNTIF($F$2:$F$101,H2) -> 10
A3: Ziro Festival Arunachal | B3: =_xlfn.MINIFS(Festival_Data_Clean!$G$2:$G$101,Festival_Data_Clean!$A$2:$A$101,A3) -> 726 | C3: =_xlfn.MAXIFS(Festival_Data_Clean!$G$2:$G$101,Festival_Data_Clean!$A$2:$A$101,A3) -> 4564 | D3: =C3-B3 -> 3838 | F3: =IF(D3>0,"Yes","No") -> Yes | H3: No | I3: =COUNTIF($F$2:$F$101,H3) -> 0
A4: VH1 Supersonic Delhi | B4: =_xlfn.MINIFS(Festival_Data_Clean!$G$2:$G$101,Festival_Data_Clean!$A$2:$A$101,A4) -> 2144 | C4: =_xlfn.MAXIFS(Festival_Data_Clean!$G$2:$G$101,Festival_Data_Clean!$A$2:$A$101,A4) -> 4849 | D4: =C4-B4 -> 2705 | F4: =IF(D4>0,"Yes","No") -> Yes
A5: Hornbill Festival Nagaland | B5: =_xlfn.MINIFS(Festival_Data_Clean!$G$2:$G$101,Festival_Data_Clean!$A$2:$A$101,A5) -> 1886 | C5: =_xlfn.MAXIFS(Festival_Data_Clean!$G$2:$G$101,Festival_Data_Clean!$A$2:$A$101,A5) -> 6972 | D5: =C5-B5 -> 5086 | F5: =IF(D5>0,"Yes","No") -> Yes
A6: Bollywood Music Project | B6: =_xlfn.MINIFS(Festival_Data_Clean!$G$2:$G$101,Festival_Data_Clean!$A$2:$A$101,A6) -> 625 | C6: =_xlfn.MAXIFS(Festival_Data_Clean!$G$2:$G$101,Festival_Data_Clean!$A$2:$A$101,A6) -> 5391.4 | D6: =C6-B6 -> 4766.4 | F6: =IF(D6>0,"Yes","No") -> Yes
A7: Lollapalooza Mumbai | B7: =_xlfn.MINIFS(Festival_Data_Clean!$G$2:$G$101,Festival_Data_Clean!$A$2:$A$101,A7) -> 929 | C7: =_xlfn.MAXIFS(Festival_Data_Clean!$G$2:$G$101,Festival_Data_Clean!$A$2:$A$101,A7) -> 5397 | D7: =C7-B7 -> 4468 | F7: =IF(D7>0,"Yes","No") -> Yes
A8: Sunburn Goa | B8: =_xlfn.MINIFS(Festival_Data_Clean!$G$2:$G$101,Festival_Data_Clean!$A$2:$A$101,A8) -> 798 | C8: =_xlfn.MAXIFS(Festival_Data_Clean!$G$2:$G$101,Festival_Data_Clean!$A$2:$A$101,A8) -> 4765.6 | D8: =C8-B8 -> 3967.6 | F8: =IF(D8>0,"Yes","No") -> Yes
A9: Supersonic Bengaluru | B9: =_xlfn.MINIFS(Festival_Data_Clean!$G$2:$G$101,Festival_Data_Clean!$A$2:$A$101,A9) -> 528 | C9: =_xlfn.MAXIFS(Festival_Data_Clean!$G$2:$G$101,Festival_Data_Clean!$A$2:$A$101,A9) -> 4046 | D9: =C9-B9 -> 3518 | F9: =IF(D9>0,"Yes","No") -> Yes
A10: Magnetic Fields Rajasthan | B10: =_xlfn.MINIFS(Festival_Data_Clean!$G$2:$G$101,Festival_Data_Clean!$A$2:$A$101,A10) -> 1244.6 | C10: =_xlfn.MAXIFS(Festival_Data_Clean!$G$2:$G$101,Festival_Data_Clean!$A$2:$A$101,A10) -> 3977 | D10: =C10-B10 -> 2732.4 | F10: =IF(D10>0,"Yes","No") -> Yes
A11: Goa Tribal Festival | B11: =_xlfn.MINIFS(Festival_Data_Clean!$G$2:$G$101,Festival_Data_Clean!$A$2:$A$101,A11) -> 1381 | C11: =_xlfn.MAXIFS(Festival_Data_Clean!$G$2:$G$101,Festival_Data_Clean!$A$2:$A$101,A11) -> 4459 | D11: =C11-B11 -> 3078 | F11: =IF(D11>0,"Yes","No") -> Yes

Sheet Stage4_Q1
A1: Artist List | B1: Avg Attendance | D1: Sorted Artist | E1: Avg Attendance
A2: =Artist_Popularity_Clean!A2 -> Diljit Dosanjh | B2: =Artist_Popularity_Clean!D2 -> 33738 | D2: {=_xlfn.SORTBY(A2:B11,B2:B11,-1)} -> Badshah | E2: 36448
A3: =Artist_Popularity_Clean!A3 -> Honey Singh | B3: =Artist_Popularity_Clean!D3 -> 35223 | D3: Honey Singh | E3: 35223
A4: =Artist_Popularity_Clean!A4 -> Mika Singh | B4: =Artist_Popularity_Clean!D4 -> 11057 | D4: Diljit Dosanjh | E4: 33738
A5: =Artist_Popularity_Clean!A5 -> Arijit Singh | B5: =Artist_Popularity_Clean!D5 -> 25729 | D5: Arijit Singh | E5: 25729
A6: =Artist_Popularity_Clean!A6 -> Ed Sheeran | B6: =Artist_Popularity_Clean!D6 -> 18609 | D6: Bryan Adams | E6: 21632.556
A7: =Artist_Popularity_Clean!A7 -> Bryan Adams | B7: =Artist_Popularity_Clean!D7 -> 21632.556 | D7: DJ Snake | E7: 19089
A8: =Artist_Popularity_Clean!A8 -> DJ Snake | B8: =Artist_Popularity_Clean!D8 -> 19089 | D8: Ed Sheeran | E8: 18609
A9: =Artist_Popularity_Clean!A9 -> Martin Garrix | B9: =Artist_Popularity_Clean!D9 -> 11603 | D9: Martin Garrix | E9: 11603
A10: =Artist_Popularity_Clean!A10 -> Badshah | B10: =Artist_Popularity_Clean!D10 -> 36448 | D10: Mika Singh | E10: 11057
A11: =Artist_Popularity_Clean!A11 -> Shreya Ghoshal | B11: =Artist_Popularity_Clean!D11 -> 3197 | D11: Shreya Ghoshal | E11: 3197

Sheet Stage4_Q2
A1: Genre | B1: Artist Count
A2: {=_xlfn.UNIQUE(Artist_Popularity_Clean!B2:B11)} -> Punjabi | B2: =COUNTIF(Artist_Popularity_Clean!$B$2:$B$11,A2) -> 1
A3: Hip-Hop | B3: =COUNTIF(Artist_Popularity_Clean!$B$2:$B$11,A3) -> 1
A4: Bollywood | B4: =COUNTIF(Artist_Popularity_Clean!$B$2:$B$11,A4) -> 3
A5: International Pop | B5: =COUNTIF(Artist_Popularity_Clean!$B$2:$B$11,A5) -> 1
A6: Rock | B6: =COUNTIF(Artist_Popularity_Clean!$B$2:$B$11,A6) -> 1
A7: EDM | B7: =COUNTIF(Artist_Popularity_Clean!$B$2:$B$11,A7) -> 2
A8: Classical/Bollywood | B8: =COUNTIF(Artist_Popularity_Clean!$B$2:$B$11,A8) -> 1

Sheet Stage4_Q3
A1: Artist | B1: Avg Artist Price | C1: Avg Attendance | D1: Merchandise Revenue | E1: Revenue Proxy | F1: Revenue Proxy Per Attendance | G1: Artist Type | I1: Artist Type | J1: Average Attendance | K1: Total Revenue Proxy | L1: Average Revenue Proxy per Attendee
A2: =Artist_Popularity_Clean!A2 -> Diljit Dosanjh | B2: =Artist_Popularity_Clean!C2 -> 2027 | C2: =Artist_Popularity_Clean!D2 -> 33738 | D2: =Artist_Popularity_Clean!G2 -> 22334556 | E2: =B2*C2+D2 -> 90721482 | F2: =E2/C2 -> 2689 | G2: =IF(OR(A2="Bryan Adams",A2="DJ Snake",A2="Martin Garrix",A2="Ed Sheeran"),"International","Local") -> Local | I2: Local | J2: =AVERAGEIF($G$2:$G$11,I2,$C$2:$C$11) -> 24232 | K2: =SUMIF($G$2:$G$11,I2,$E$2:$E$11) -> 426028651 | L2: =AVERAGEIF($G$2:$G$11,I2,$F$2:$F$11) -> 2895.6667
A3: =Artist_Popularity_Clean!A3 -> Honey Singh | B3: =Artist_Popularity_Clean!C3 -> 1573 | C3: =Artist_Popularity_Clean!D3 -> 35223 | D3: =Artist_Popularity_Clean!G3 -> 25360560 | E3: =B3*C3+D3 -> 80766339 | F3: =E3/C3 -> 2293 | G3: =IF(OR(A3="Bryan Adams",A3="DJ Snake",A3="Martin Garrix",A3="Ed Sheeran"),"International","Local") -> Local | I3: International | J3: =AVERAGEIF($G$2:$G$11,I3,$C$2:$C$11) -> 17733.389 | K3: =SUMIF($G$2:$G$11,I3,$E$2:$E$11) -> 1.7190398e+08 | L3: =AVERAGEIF($G$2:$G$11,I3,$F$2:$F$11) -> 2527.7928
A4: =Artist_Popularity_Clean!A4 -> Mika Singh | B4: =Artist_Popularity_Clean!C4 -> 1025 | C4: =Artist_Popularity_Clean!D4 -> 11057 | D4: =Artist_Popularity_Clean!G4 -> 7983154 | E4: =B4*C4+D4 -> 19316579 | F4: =E4/C4 -> 1747 | G4: =IF(OR(A4="Bryan Adams",A4="DJ Snake",A4="Martin Garrix",A4="Ed Sheeran"),"International","Local") -> Local
A5: =Artist_Popularity_Clean!A5 -> Arijit Singh | B5: =Artist_Popularity_Clean!C5 -> 2437 | C5: =Artist_Popularity_Clean!D5 -> 25729 | D5: =Artist_Popularity_Clean!G5 -> 18730712 | E5: =B5*C5+D5 -> 81432285 | F5: =E5/C5 -> 3165 | G5: =IF(OR(A5="Bryan Adams",A5="DJ Snake",A5="Martin Garrix",A5="Ed Sheeran"),"International","Local") -> Local
A6: =Artist_Popularity_Clean!A6 -> Ed Sheeran | B6: =Artist_Popularity_Clean!C6 -> 3436 | C6: =Artist_Popularity_Clean!D6 -> 18609 | D6: =Artist_Popularity_Clean!G6 -> 4856949 | E6: =B6*C6+D6 -> 68797473 | F6: =E6/C6 -> 3697 | G6: =IF(OR(A6="Bryan Adams",A6="DJ Snake",A6="Martin Garrix",A6="Ed Sheeran"),"International","Local") -> International
A7: =Artist_Popularity_Clean!A7 -> Bryan Adams | B7: =Artist_Popularity_Clean!C7 -> 992 | C7: =Artist_Popularity_Clean!D7 -> 21632.556 | D7: =Artist_Popularity_Clean!G7 -> 8678356 | E7: =B7*C7+D7 -> 30137851 | F7: =E7/C7 -> 1393.1711 | G7: =IF(OR(A7="Bryan Adams",A7="DJ Snake",A7="Martin Garrix",A7="Ed Sheeran"),"International","Local") -> International
A8: =Artist_Popularity_Clean!A8 -> DJ Snake | B8: =Artist_Popularity_Clean!C8 -> 1431 | C8: =Artist_Popularity_Clean!D8 -> 19089 | D8: =Artist_Popularity_Clean!G8 -> 10193526 | E8: =B8*C8+D8 -> 37509885 | F8: =E8/C8 -> 1965 | G8: =IF(OR(A8="Bryan Adams",A8="DJ Snake",A8="Martin Garrix",A8="Ed Sheeran"),"International","Local") -> International
A9: =Artist_Popularity_Clean!A9 -> Martin Garrix | B9: =Artist_Popularity_Clean!C9 -> 2499 | C9: =Artist_Popularity_Clean!D9 -> 11603 | D9: =Artist_Popularity_Clean!G9 -> 6462871 | E9: =B9*C9+D9 -> 35458768 | F9: =E9/C9 -> 3056 | G9: =IF(OR(A9="Bryan Adams",A9="DJ Snake",A9="Martin Garrix",A9="Ed Sheeran"),"International","Local") -> International
A10: =Artist_Popularity_Clean!A10 -> Badshah | B10: =Artist_Popularity_Clean!C10 -> 3351 | C10: =Artist_Popularity_Clean!D10 -> 36448 | D10: =Artist_Popularity_Clean!G10 -> 20228640 | E10: =B10*C10+D10 -> 142365888 | F10: =E10/C10 -> 3906 | G10: =IF(OR(A10="Bryan Adams",A10="DJ Snake",A10="Martin Garrix",A10="Ed Sheeran"),"International","Local") -> Local
A11: =Artist_Popularity_Clean!A11 -> Shreya Ghoshal | B11: =Artist_Popularity_Clean!C11 -> 3326 | C11: =Artist_Popularity_Clean!D11 -> 3197 | D11: =Artist_Popularity_Clean!G11 -> 792856 | E11: =B11*C11+D11 -> 11426078 | F11: =E11/C11 -> 3574 | G11: =IF(OR(A11="Bryan Adams",A11="DJ Snake",A11="Martin Garrix",A11="Ed Sheeran"),"International","Local") -> Local

Sheet Stage5_Q1
A1: Festival | B1: Sponsorship Revenue | C1: Total Revenue | D1: Sponsorship Contribution % | F1: Total Sponsorship Revenue | G1: Total Revenue | H1: Overall Sponsorship Contribution %
A2: =Festival_Data_Clean!A2 -> NH7 Pune | B2: =Festival_Data_Clean!J2 -> 3680408 | C2: =Festival_Data_Clean!K2 -> 13348696 | D2: =B2/C2 -> 0.27571292 | F2: =SUM(B2:B101) -> 305330155 | G2: =SUM(C2:C101) -> 6935729638 | H2: =F2/G2 -> 0.044022788
A3: =Festival_Data_Clean!A3 -> Ziro Festival Arunachal | B3: =Festival_Data_Clean!J3 -> 2589481 | C3: =Festival_Data_Clean!K3 -> 87858495 | D3: =B3/C3 -> 0.029473314
A4: =Festival_Data_Clean!A4 -> NH7 Pune | B4: =Festival_Data_Clean!J4 -> 640053 | C4: =Festival_Data_Clean!K4 -> 132693072 | D4: =B4/C4 -> 0.00482356 | H4: Revenue Type | I4: Revenue
A5: =Festival_Data_Clean!A5 -> VH1 Supersonic Delhi | B5: =Festival_Data_Clean!J5 -> 2712686 | C5: =Festival_Data_Clean!K5 -> 36553838 | D5: =B5/C5 -> 0.074210703 | H5: Sponsorship | I5: =F2 -> 305330155
A6: =Festival_Data_Clean!A6 -> Hornbill Festival Nagaland | B6: =Festival_Data_Clean!J6 -> 1181193 | C6: =Festival_Data_Clean!K6 -> 73783833 | D6: =B6/C6 -> 0.016008832 | H6: Other Revenue | I6: =G2-F2 -> 6630399483
A7: =Festival_Data_Clean!A7 -> Ziro Festival Arunachal | B7: =Festival_Data_Clean!J7 -> 2302603 | C7: =Festival_Data_Clean!K7 -> 58605653 | D7: =B7/C7 -> 0.039289776
A8: =Festival_Data_Clean!A8 -> Ziro Festival Arunachal | B8: =Festival_Data_Clean!J8 -> 4948076 | C8: =Festival_Data_Clean!K8 -> 111635078 | D8: =B8/C8 -> 0.044323667
A9: =Festival_Data_Clean!A9 -> NH7 Pune | B9: =Festival_Data_Clean!J9 -> 1201595 | C9: =Festival_Data_Clean!K9 -> 41577735 | D9: =B9/C9 -> 0.028899963
A10: =Festival_Data_Clean!A10 -> Bollywood Music Project | B10: =Festival_Data_Clean!J10 -> 3427104 | C10: =Festival_Data_Clean!K10 -> 81824709 | D10: =B10/C10 -> 0.041883485
A11: =Festival_Data_Clean!A11 -> Lollapalooza Mumbai | B11: =Festival_Data_Clean!J11 -> 3948781 | C11: =Festival_Data_Clean!K11 -> 39768298 | D11: =B11/C11 -> 0.099294694
A12: =Festival_Data_Clean!A12 -> Hornbill Festival Nagaland | B12: =Festival_Data_Clean!J12 -> 4798020 | C12: =Festival_Data_Clean!K12 -> 75365349 | D12: =B12/C12 -> 0.063663475
A13: =Festival_Data_Clean!A13 -> Sunburn Goa | B13: =Festival_Data_Clean!J13 -> 2851905 | C13: =Festival_Data_Clean!K13 -> 76139976 | D13: =B13/C13 -> 0.03745608
A14: =Festival_Data_Clean!A14 -> Supersonic Bengaluru | B14: =Festival_Data_Clean!J14 -> 3167786 | C14: =Festival_Data_Clean!K14 -> 19328026 | D14: =B14/C14 -> 0.16389599
A15: =Festival_Data_Clean!A15 -> Magnetic Fields Rajasthan | B15: =Festival_Data_Clean!J15 -> 2897760 | C15: =Festival_Data_Clean!K15 -> 36373655 | D15: =B15/C15 -> 0.079666451
A16: =Festival_Data_Clean!A16 -> Hornbill Festival Nagaland | B16: =Festival_Data_Clean!J16 -> 4600450 | C16: =Festival_Data_Clean!K16 -> 59239606 | D16: =B16/C16 -> 0.077658349
A17: =Festival_Data_Clean!A17 -> VH1 Supersonic Delhi | B17: =Festival_Data_Clean!J17 -> 795307 | C17: =Festival_Data_Clean!K17 -> 28195711 | D17: =B17/C17 -> 0.028206666
A18: =Festival_Data_Clean!A18 -> Lollapalooza Mumbai | B18: =Festival_Data_Clean!J18 -> 2188470 | C18: =Festival_Data_Clean!K18 -> 54311142 | D18: =B18/C18 -> 0.040295047
... A101: =Festival_Data_Clean!A101 -> Ziro Festival Arunachal | B101: =Festival_Data_Clean!J101 -> 835232 | C101: =Festival_Data_Clean!K101 -> 42318622 | D101: =B101/C101 -> 0.019736749

Sheet Stage5_Q2
A1: Festival | B1: Ticket Price | C1: Sponsorship Revenue | D1: Price Category | F1: Price Category | G1: Avg Sponsorship Revenue | H1: Festival Count
A2: =Festival_Data_Clean!A2 -> NH7 Pune | B2: =Festival_Data_Clean!G2 -> 1253 | C2: =Festival_Data_Clean!J2 -> 3680408 | D2: =IF(B2<=1500,"₹0-1,500",IF(B2<=3000,"₹1,501-3,000",IF(B2<=4500,"₹3,001-4,500","₹4,500+"))) -> ₹0-1,500 | F2: ₹1,501-3,000 | G2: =AVERAGEIF($D$2:$D$101,F2,$C$2:$C$101) -> 3321161.6 | H2: =COUNTIF($D$2:$D$101,F2) -> 37
A3: =Festival_Data_Clean!A3 -> Ziro Festival Arunachal | B3: =Festival_Data_Clean!G3 -> 1689 | C3: =Festival_Data_Clean!J3 -> 2589481 | D3: =IF(B3<=1500,"₹0-1,500",IF(B3<=3000,"₹1,501-3,000",IF(B3<=4500,"₹3,001-4,500","₹4,500+"))) -> ₹1,501-3,000 | F3: ₹3,001-4,500 | G3: =AVERAGEIF($D$2:$D$101,F3,$C$2:$C$101) -> 3180091.2 | H3: =COUNTIF($D$2:$D$101,F3) -> 31
A4: =Festival_Data_Clean!A4 -> NH7 Pune | B4: =Festival_Data_Clean!G4 -> 6813.8 | C4: =Festival_Data_Clean!J4 -> 640053 | D4: =IF(B4<=1500,"₹0-1,500",IF(B4<=3000,"₹1,501-3,000",IF(B4<=4500,"₹3,001-4,500","₹4,500+"))) -> ₹4,500+ | F4: ₹4,500+ | G4: =AVERAGEIF($D$2:$D$101,F4,$C$2:$C$101) -> 2894398.4 | H4: =COUNTIF($D$2:$D$101,F4) -> 15
A5: =Festival_Data_Clean!A5 -> VH1 Supersonic Delhi | B5: =Festival_Data_Clean!G5 -> 2144 | C5: =Festival_Data_Clean!J5 -> 2712686 | D5: =IF(B5<=1500,"₹0-1,500",IF(B5<=3000,"₹1,501-3,000",IF(B5<=4500,"₹3,001-4,500","₹4,500+"))) -> ₹1,501-3,000 | F5: ₹0-1,500 | G5: =AVERAGEIF($D$2:$D$101,F5,$C$2:$C$101) -> 2379316.1 | H5: =COUNTIF($D$2:$D$101,F5) -> 17
A6: =Festival_Data_Clean!A6 -> Hornbill Festival Nagaland | B6: =Festival_Data_Clean!G6 -> 1886 | C6: =Festival_Data_Clean!J6 -> 1181193 | D6: =IF(B6<=1500,"₹0-1,500",IF(B6<=3000,"₹1,501-3,000",IF(B6<=4500,"₹3,001-4,500","₹4,500+"))) -> ₹1,501-3,000
A7: =Festival_Data_Clean!A7 -> Ziro Festival Arunachal | B7: =Festival_Data_Clean!G7 -> 3984 | C7: =Festival_Data_Clean!J7 -> 2302603 | D7: =IF(B7<=1500,"₹0-1,500",IF(B7<=3000,"₹1,501-3,000",IF(B7<=4500,"₹3,001-4,500","₹4,500+"))) -> ₹3,001-4,500
A8: =Festival_Data_Clean!A8 -> Ziro Festival Arunachal | B8: =Festival_Data_Clean!G8 -> 1162.4 | C8: =Festival_Data_Clean!J8 -> 4948076 | D8: =IF(B8<=1500,"₹0-1,500",IF(B8<=3000,"₹1,501-3,000",IF(B8<=4500,"₹3,001-4,500","₹4,500+"))) -> ₹0-1,500
A9: =Festival_Data_Clean!A9 -> NH7 Pune | B9: =Festival_Data_Clean!G9 -> 840 | C9: =Festival_Data_Clean!J9 -> 1201595 | D9: =IF(B9<=1500,"₹0-1,500",IF(B9<=3000,"₹1,501-3,000",IF(B9<=4500,"₹3,001-4,500","₹4,500+"))) -> ₹0-1,500
